import { describe, expect, test } from "bun:test"
import * as r from "./index.mts"
import * as rutil from "./lazy.mts"

describe("共通ユーティリティ関数のテスト", () => {
  describe("map関数のテスト", () => {
    const f = rutil.map((v: number) => v + 1)

    test("map関数はSuccess型の値を受け取った時、引数の関数を実行してSuccess型を返す", () => {
      expect(f(r.succeed(1))).toStrictEqual(r.succeed(2))
    })

    test("map関数はFailure型の値を受け取った時、そのままFailure型を返す", () => {
      expect(f(r.fail("error"))).toStrictEqual(r.fail("error"))
    })
  })

  describe("mapError関数のテスト", () => {
    const f = rutil.mapError((v: number) => v + 1)

    test("mapError関数はSuccess型の値を受け取った時、そのままSuccess型を返す", () => {
      expect(f(r.succeed(1))).toStrictEqual(r.succeed(1))
    })

    test("mapError関数はFailure型の値を受け取った時、関数を実行してFailure型を返す", () => {
      expect(f(r.fail(1))).toStrictEqual(r.fail(2))
    })
  })

  describe("flatMap関数のテスト", () => {
    const f = rutil.flatMap((v: number) => {
      switch (v) {
        case 1:
          return r.succeed(v + 1)
        default:
          return r.fail("error")
      }
    })

    test("flatMap関数はSuccess型の値を受け取った時、引数の関数を実行してSuccess型を返す", () => {
      expect(f(r.succeed(1))).toStrictEqual(r.succeed(2))
    })

    test("flatMap関数はSuccess型の値を受け取った時、引数の関数を実行してFailure型を返す", () => {
      expect(f(r.succeed(2))).toStrictEqual(r.fail("error"))
    })

    test("flatMap関数はFailure型の値を受け取った時、そのままFailure型を返す", () => {
      expect(f(r.fail(1))).toStrictEqual(r.fail(1))
    })
  })

  describe("flatMapError関数のテスト", () => {
    const f = rutil.flatMapError((v: number) => {
      switch (v) {
        case 1:
          return r.succeed(v + 1)
        default:
          return r.fail("error")
      }
    })

    test("flatMapError関数はSuccess型の値を受け取った時、そのままSuccess型を返す", () => {
      expect(f(r.succeed(1))).toStrictEqual(r.succeed(1))
    })

    test("flatMapError関数はFailure型の値を受け取った時、引数の関数を実行してSuccess型を返す", () => {
      expect(f(r.fail(1))).toStrictEqual(r.succeed(2))
    })

    test("flatMapError関数はFailure型の値を受け取った時、引数の関数を実行してFailure型を返す", () => {
      expect(f(r.fail(2))).toStrictEqual(r.fail("error"))
    })
  })

  describe("tryCatch関数のテスト", () => {
    test("tryCatch関数は例外が投げられなければ、Success型を返す", () => {
      expect(
        rutil.tryCatch(
          (x: number) => x + 1,
          () => "error",
        )(1),
      ).toStrictEqual(r.succeed(2))
    })

    test("tryCatch関数は例外が投げられた時、Failure型を返す", () => {
      expect(
        rutil.tryCatch(
          (x: number) => {
            throw x
          },
          () => "error",
        )(1),
      ).toStrictEqual(r.fail("error"))
    })
  })

  describe("tryCatchAsync関数のテスト", () => {
    test("tryCatchAsync関数は非同期関数で例外が投げられなければ、PromiseLike<Success>型を返す", async () => {
      expect(
        await rutil.tryCatchAsync(
          async (x: number) => x + 1,
          () => "error",
        )(1),
      ).toStrictEqual(r.succeed(2))
    })

    test("tryCatchAsync関数は非同期関数で例外が投げられると、PromiseLike<Failure>型を返す", async () => {
      expect(
        await rutil.tryCatchAsync(
          async (x: number) => {
            throw x
          },
          () => "error",
        )(1),
      ).toStrictEqual(r.fail("error"))
    })
  })
})
